Workbook
Name Slicer_Brand: #N/A
Name Slicer_Category: #N/A
Name Slicer_Region_Clean: #N/A

Sheet Products

Sheet Return

Sheet Dashboard
B3: Total Sales | C3: (YoY Comparison) | E3: Total Profit | F3: (YoY Comparison) | H3: Total Orders | I3: YoY Comparison | K3: Return Rate | M3: Profit Margin
B4: =GETPIVOTDATA("Sales",Analysis!$A$3) -> 27988522 | C4: =Analysis!J5 -> -0.83207689 | E4: =GETPIVOTDATA("Profit",Analysis!$A$13) -> 4637875.4 | F4: =Analysis!J15 -> -0.83532478 | H4: =GETPIVOTDATA("OrderID",Analysis!$A$21) -> 11200 | I4: =Analysis!J23 -> -0.83333333 | K4: =GETPIVOTDATA("OrderID",Analysis!$A$31,"Return Status","Returned") -> 0.10035714 | M4: =GETPIVOTDATA("Profit Margin",Analysis!$A$37) -> 0.16599267
U13: x

Sheet Analysis
A2: Total Sales
A3: Sum of Sales | D3: Column Labels
A4: 27988522 | D4: 2023 | E4: 2024 | F4: Grand Total | H4: Latest Year | I4: Last Year | J4: YoY Comparison
C5: Sum of Sales | D5: 23964353 | E5: 4024168.6 | F5: 27988522 | H5: =GETPIVOTDATA("Sales",$C$3,"Years (Order Date)",2024) -> 4024168.6 | I5: =GETPIVOTDATA("Sales",$C$3,"Years (Order Date)",2023) -> 23964353 | J5: =(H5-I5)/I5 -> -0.83207689
A12: Total Profit | D12: Column Labels
A13: Sum of Profit | D13: 2023 | E13: 2024 | F13: Grand Total
A14: 4637875.4 | C14: Sum of Profit | D14: 3982119.1 | E14: 655756.35 | F14: 4637875.4 | H14: Latest Year | I14: Last Year | J14: YoY Comparison
H15: =GETPIVOTDATA("Profit",$C$12,"Years (Order Date)",2024) -> 655756.35 | I15: =GETPIVOTDATA("Profit",$C$12,"Years (Order Date)",2023) -> 3982119.1 | J15: =(H15-I15)/I15 -> -0.83532478
A20: Order Count
A21: Count of OrderID | D21: Column Labels
A22: 11200 | D22: 2023 | E22: 2024 | F22: Grand Total | H22: Latest Year | I22: Last Year | J22: YoY Comparison
H23: =GETPIVOTDATA("OrderID",$C$21,"Years (Order Date)",2024) -> 1600 | I23: =GETPIVOTDATA("OrderID",$C$21,"Years (Order Date)",2023) -> 9600 | J23: =(H23-I23)/I23 -> -0.83333333
C26: Count of OrderID | D26: 9600 | E26: 1600 | F26: 11200
A30: Return Rate %
B31: Column Labels
B32: Not Returned | C32: Returned | D32: Grand Total
A33: Count of OrderID | B33: 0.89964286 | C33: 0.10035714 | D33: 1
A36: Profit Margin %
A37: Average of Profit Margin
A38: 0.16599267
A42: Row Labels | B42: Sum of Sales
A43: 44957 | B43: 1936163.8
A44: 44985 | B44: 1968022.9
A45: 45016 | B45: 2007815.6
A46: 45046 | B46: 2001662.7
A47: 45077 | B47: 1967145.6
A48: 45107 | B48: 2007811.8
A49: 45138 | B49: 2016326.4
A50: 45169 | B50: 1983777.4
A51: 45199 | B51: 1991132.8
A52: 45230 | B52: 2070128.9
A53: 45260 | B53: 2015438.2
A54: 45291 | B54: 1998926.9
... A56: 45351 | B56: 2069878.9
A57: Grand Total | B57: 27988522
A65: Row Labels | B65: Sum of Sales | C65: Average of Profit Margin
A66: 44957 | B66: 1936163.8 | C66: 0.17022167
A67: 44985 | B67: 1968022.9 | C67: 0.1639608
A68: 45016 | B68: 2007815.6 | C68: 0.16871927
A69: 45046 | B69: 2001662.7 | C69: 0.16408619
...

Sheet EDA questions
A3: Row Labels | B3: Sum of Sales | C3: Average of Profit Margin
A4: 2023 | B4: 23964353 | C4: 0.16606655
A5: Qtr1 | B5: 5912002.4 | C5: 0.16763392
A6: Jan | B6: 1936163.8 | C6: 0.17022167
A7: 44957 | B7: 1936163.8 | C7: 0.17022167
A8: Feb | B8: 1968022.9 | C8: 0.1639608
A9: 44985 | B9: 1968022.9 | C9: 0.1639608
A10: Mar | B10: 2007815.6 | C10: 0.16871927
A11: 45016 | B11: 2007815.6 | C11: 0.16871927
A12: Qtr2 | B12: 5976620.1 | C12: 0.1665462
A13: Apr | B13: 2001662.7 | C13: 0.16408619
A14: 45046 | B14: 2001662.7 | C14: 0.16408619
A15: May | B15: 1967145.6 | C15: 0.16525647
A16: 45077 | B16: 1967145.6 | C16: 0.16525647
A17: Jun | B17: 2007811.8 | C17: 0.17029594
A18: 45107 | B18: 2007811.8 | C18: 0.17029594
A19: Qtr3 | B19: 5991236.5 | C19: 0.16519329
A20: Jul | B20: 2016326.4 | C20: 0.16709941
A21: 45138 | B21: 2016326.4 | C21: 0.16709941
A22: Aug | B22: 1983777.4 | C22: 0.16351077
A23: 45169 | B23: 1983777.4 | C23: 0.16351077 | E23: Row Labels | F23: Sum of Sales
A24: Sep | B24: 1991132.8 | C24: 0.16496969 | E24: 2023 | F24: 23964353
A25: 45199 | B25: 1991132.8 | C25: 0.16496969 | E25: Qtr1 | F25: 5912002.3
A26: Qtr4 | B26: 6084494 | C26: 0.16489281 | E26: Jan | F26: 1936163.8
A27: Oct | B27: 2070128.9 | C27: 0.1630325 | E27: 44957 | F27: 1936163.8
A28: 45230 | B28: 2070128.9 | C28: 0.1630325 | E28: Feb | F28: 1968022.9
A29: Nov | B29: 2015438.2 | C29: 0.16523381 | E29: 44985 | F29: 1968022.9
A30: 45260 | B30: 2015438.2 | C30: 0.16523381 | E30: Mar | F30: 2007815.6
A31: Dec | B31: 1998926.9 | C31: 0.16641212 | E31: 45016 | F31: 2007815.6
A32: 45291 | B32: 1998926.9 | C32: 0.16641212 | E32: Qtr2 | F32: 5976620.1
A33: 2024 | B33: 4024168.6 | C33: 0.16554938 | E33: Apr | F33: 2001662.7
A34: Qtr1 | B34: 4024168.6 | C34: 0.16554938 | E34: 45046 | F34: 2001662.7
A35: Jan | B35: 1954289.7 | C35: 0.16450383 | E35: May | F35: 1967145.6
A36: 45322 | B36: 1954289.7 | C36: 0.16450383 | E36: 45077 | F36: 1967145.6
A37: Feb | B37: 2069878.9 | C37: 0.16659494 | E37: Jun | F37: 2007811.8
A38: 45351 | B38: 2069878.9 | C38: 0.16659494 | E38: 45107 | F38: 2007811.8
A39: Grand Total | B39: 27988522 | C39: 0.16599267 | E39: Qtr3 | F39: 5991236.5
E40: Jul | F40: 2016326.4
E41: 45138 | F41: 2016326.4
E42: Aug | F42: 1983777.4 | L42: Row Labels | M42: Sum of Sales
...

Sheet Quaterly Sales Trend
A3: Row Labels | B3: Sum of Sales
A4: (blank) | B4: 1117.79 | N4: 1 | O4: =N4+2 -> 3 | P4: =INT(O4/3) -> 1 | Q4: ="Q"&P4&"-"&YEAR(TODAY()) -> Q1-2026
A5: Q1-2024 | B5: 4024168.6 | N5: 2 | O5: =N5+2 -> 4 | P5: =INT(O5/3) -> 1 | Q5: ="Q"&P5&"-"&YEAR(TODAY()) -> Q1-2026
A6: Q1-2023 | B6: 5910884.6 | N6: 3 | O6: =N6+2 -> 5 | P6: =INT(O6/3) -> 1 | Q6: ="Q"&P6&"-"&YEAR(TODAY()) -> Q1-2026
A7: Q2-2023 | B7: 5976620.1 | N7: 4 | O7: =N7+2 -> 6 | P7: =INT(O7/3) -> 2 | Q7: ="Q"&P7&"-"&YEAR(TODAY()) -> Q2-2026
A8: Q3-2023 | B8: 5991236.5 | N8: 5 | O8: =N8+2 -> 7 | P8: =INT(O8/3) -> 2 | Q8: ="Q"&P8&"-"&YEAR(TODAY()) -> Q2-2026
A9: Q4-2023 | B9: 6084494 | N9: 6 | O9: =N9+2 -> 8 | P9: =INT(O9/3) -> 2 | Q9: ="Q"&P9&"-"&YEAR(TODAY()) -> Q2-2026
A10: Grand Total | B10: 27988522 | N10: 7 | O10: =N10+2 -> 9 | P10: =INT(O10/3) -> 3 | Q10: ="Q"&P10&"-"&YEAR(TODAY()) -> Q3-2026
N11: 8 | O11: =N11+2 -> 10 | P11: =INT(O11/3) -> 3 | Q11: ="Q"&P11&"-"&YEAR(TODAY()) -> Q3-2026
N12: 9 | O12: =N12+2 -> 11 | P12: =INT(O12/3) -> 3 | Q12: ="Q"&P12&"-"&YEAR(TODAY()) -> Q3-2026
N13: 10 | O13: =N13+2 -> 12 | P13: =INT(O13/3) -> 4 | Q13: ="Q"&P13&"-"&YEAR(TODAY()) -> Q4-2026

Sheet SalesData
A1: OrderID | B1: Order Date | C1: Customer Name | D1: City | E1: Phone Number | F1: Product | G1: ProductCode | H1: Brand | I1: Category | J1: Region | K1: Sales | L1: Profit | M1: Region_Clean | N1: Profit Margin | O1: Sales Size | P1: Profitability Flag | Q1: ReturnReason | R1: Return Status | S1: Return (1 or 0) | T1: UnitPrice | U1: Order Month(MMM-YY) | V1: Order Date(Q)
A2: ORD-202301-00001 | B2: 44932 | C2: Lina Gomez | D2: Mumbai | E2: 8196001338 | F2: jacket | G2: PRD-108-JAC | H2: NorthFace | I2: Fashion | J2: N | K2: 1117.79 | L2: 211.38 | M2: North | N2: 0.18910529 | O2: Large Order | P2: Medium Profit | R2: Not Returned | S2: =IF(SalesData[[#This Row],[Return Status]]="Returned",1,0) -> 0 | T2: 2085.91 | U2: =EOMONTH(SalesData[[#This Row],[Order Date]],0) -> 44957
A3: ORD-202301-00002 | B3: 44947 | C3: Eva Adams | D3: Mumbai | E3: 1615594078 | F3: Shirt | G3: PRD-101-SHI | H3: Adidas | I3: Fashion | J3: North | K3: 2895.21 | L3: 637.62 | M3: North | N3: 0.22023273 | O3: Large Order | P3: High Profit | R3: Not Returned | S3: =IF(SalesData[[#This Row],[Return Status]]="Returned",1,0) -> 0 | T3: 2821.33 | U3: =EOMONTH(SalesData[[#This Row],[Order Date]],0) -> 44957 | V3: ="Q"&INT((MONTH(SalesData[[#This Row],[Order Date]])+2)/3)&"-"&YEAR(SalesData[[#This Row],[Order Date]]) -> Q1-2023
A4: ORD-202301-00006 | B4: 44941 | C4: Ishan Kapoor | D4: New Delhi | E4: 9570154303 | F4: SHIRT | G4: PRD-101-SHI | H4: Adidas | I4: Fashion | J4: East | K4: 659.39 | L4: 104.4 | M4: East | N4: 0.15832815 | O4: Medium Order | P4: Medium Profit | R4: Not Returned | S4: =IF(SalesData[[#This Row],[Return Status]]="Returned",1,0) -> 0 | T4: 2821.33 | U4: =EOMONTH(SalesData[[#This Row],[Order Date]],0) -> 44957 | V4: ="Q"&INT((MONTH(SalesData[[#This Row],[Order Date]])+2)/3)&"-"&YEAR(SalesData[[#This Row],[Order Date]]) -> Q1-2023
A5: ORD-202301-00003 | B5: 44930 | C5: Nikhil Roy | D5: Hyderabad | E5: 2553419283 | F5: PHONE | G5: PRD-106-PHO | H5: Apple | I5: Electronics | J5: North | K5: 3429.38 | L5: 883.31 | M5: North | N5: 0.25757134 | O5: Large Order | P5: High Profit | R5: Not Returned | S5: =IF(SalesData[[#This Row],[Return Status]]="Returned",1,0) -> 0 | T5: 2788.38 | U5: =EOMONTH(SalesData[[#This Row],[Order Date]],0) -> 44957 | V5: ="Q"&INT((MONTH(SalesData[[#This Row],[Order Date]])+2)/3)&"-"&YEAR(SalesData[[#This Row],[Order Date]]) -> Q1-2023
A6: ORD-202301-00004 | B6: 44942 | C6: Eva Adams | D6: Hyderabad | E6: 3767242388 | F6: SUNGLASSES | G6: PRD-109-SUN | H6: RayBan | I6: Accessories | J6: N | K6: 2557.44 | L6: 139.5 | M6: North | N6: 0.054546734 | O6: Large Order | P6: Low Profit | R6: Not Returned | S6: =IF(SalesData[[#This Row],[Return Status]]="Returned",1,0) -> 0 | U6: =EOMONTH(SalesData[[#This Row],[Order Date]],0) -> 44957 | V6: ="Q"&INT((MONTH(SalesData[[#This Row],[Order Date]])+2)/3)&"-"&YEAR(SalesData[[#This Row],[Order Date]]) -> Q1-2023
A7: ORD-202301-00007 | B7: 44956 | C7: David Lee | D7: Hyderabad | E7: 7871331509 | F7: Sunglasses | G7: PRD-109-SUN | H7: Unknown | I7: Accessories | J7: North | K7: 1160.13 | L7: 318.41 | M7: North | N7: 0.27446062 | O7: Large Order | P7: High Profit | R7: Not Returned | S7: =IF(SalesData[[#This Row],[Return Status]]="Returned",1,0) -> 0 | U7: =EOMONTH(SalesData[[#This Row],[Order Date]],0) -> 44957 | V7: ="Q"&INT((MONTH(SalesData[[#This Row],[Order Date]])+2)/3)&"-"&YEAR(SalesData[[#This Row],[Order Date]]) -> Q1-2023
A8: ORD-202301-00009 | B8: 44953 | C8: Charlie Brown | D8: Mumbai | E8: 7810801326 | F8: HEADPHONES | G8: PRD-103-HEA | H8: Sony | I8: Electronics | J8: S | K8: 1907.29 | L8: 564.62 | M8: South | N8: 0.29603259 | O8: Large Order | P8: High Profit | R8: Not Returned | S8: =IF(SalesData[[#This Row],[Return Status]]="Returned",1,0) -> 0 | T8: 2183.56 | U8: =EOMONTH(SalesData[[#This Row],[Order Date]],0) -> 44957 | V8: ="Q"&INT((MONTH(SalesData[[#This Row],[Order Date]])+2)/3)&"-"&YEAR(SalesData[[#This Row],[Order Date]]) -> Q1-2023
A9: ORD-202301-00005 | B9: 44934 | C9: Grace Chen | D9: Ahmedabad | E9: 8480184514 | F9: Tablet | G9: PRD - 107 - TAB | H9: Samsung | I9: Electronics | J9: W | K9: 4860 | L9: 1145.65 | M9: West | N9: 0.23573045 | O9: Large Order | P9: High Profit | R9: Not Returned | S9: =IF(SalesData[[#This Row],[Return Status]]="Returned",1,0) -> 0 | U9: =EOMONTH(SalesData[[#This Row],[Order Date]],0) -> 44957 | V9: ="Q"&INT((MONTH(SalesData[[#This Row],[Order Date]])+2)/3)&"-"&YEAR(SalesData[[#This Row],[Order Date]]) -> Q1-2023
A10: ORD-202301-00012 | B10: 44930 | C10: Frank Miller | D10: Kolkata | E10: 9808412411 | F10: Watch | G10: PRD-104-WAT | H10: Fossil | I10: Accessories | J10: North | K10: 1033.91 | L10: 208.07 | M10: North | N10: 0.20124576 | O10: Large Order | P10: High Profit | R10: Not Returned | S10: =IF(SalesData[[#This Row],[Return Status]]="Returned",1,0) -> 0 | T10: 2420.28 | U10: =EOMONTH(SalesData[[#This Row],[Order Date]],0) -> 44957 | V10: ="Q"&INT((MONTH(SalesData[[#This Row],[Order Date]])+2)/3)&"-"&YEAR(SalesData[[#This Row],[Order Date]]) -> Q1-2023
A11: ORD-202301-00361 | B11: 44948 | C11: Bob Johnson | D11: Chennai | E11: 8202368485 | F11: Camera | G11: PRD-110-CAM | H11: Canon | I11: Electronics | J11: N | K11: 2424.45 | L11: 415.59 | M11: North | N11: 0.1714162 | O11: Large Order | P11: Medium Profit | Q11: missing parts | R11: Returned | S11: =IF(SalesData[[#This Row],[Return Status]]="Returned",1,0) -> 1 | U11: =EOMONTH(SalesData[[#This Row],[Order Date]],0) -> 44957 | V11: ="Q"&INT((MONTH(SalesData[[#This Row],[Order Date]])+2)/3)&"-"&YEAR(SalesData[[#This Row],[Order Date]]) -> Q1-2023
A12: ORD-202301-00008 | B12: 44950 | C12: Ishan Kapoor | D12: Ahmedabad | E12: 3763116566 | F12: Camera | G12: PRD-110-CAM | H12: Canon | I12: Electronics | J12: N | K12: 2025.05 | L12: 246.27 | M12: North | N12: 0.12161181 | O12: Large Order | P12: Medium Profit | R12: Not Returned | S12: =IF(SalesData[[#This Row],[Return Status]]="Returned",1,0) -> 0 | U12: =EOMONTH(SalesData[[#This Row],[Order Date]],0) -> 44957 | V12: ="Q"&INT((MONTH(SalesData[[#This Row],[Order Date]])+2)/3)&"-"&YEAR(SalesData[[#This Row],[Order Date]]) -> Q1-2023
A13: ORD-202301-00011 | B13: 44938 | C13: Jaya Rao | D13: Hyderabad | E13: 4353462475 | F13: Tablet | G13: PRD-107-TAB | H13: Samsung | I13: Electronics | J13: South | K13: 384.84 | L13: 33.69 | M13: South | N13: 0.087542875 | O13: Small Order | P13: Low Profit | R13: Not Returned | S13: =IF(SalesData[[#This Row],[Return Status]]="Returned",1,0) -> 0 | T13: 2081.52 | U13: =EOMONTH(SalesData[[#This Row],[Order Date]],0) -> 44957 | V13: ="Q"&INT((MONTH(SalesData[[#This Row],[Order Date]])+2)/3)&"-"&YEAR(SalesData[[#This Row],[Order Date]]) -> Q1-2023
A14: ORD-202301-00010 | B14: 44940 | C14: Lina Gomez | D14: New Delhi | E14: 9805009788 | F14: Jacket | G14: PRD - 108 - JAC | H14: NorthFace | I14: Fashion | J14: East | K14: 3382.56 | L14: 316.29 | M14: East | N14: 0.093506102 | O14: Large Order | P14: Low Profit | R14: Not Returned | S14: =IF(SalesData[[#This Row],[Return Status]]="Returned",1,0) -> 0 | U14: =EOMONTH(SalesData[[#This Row],[Order Date]],0) -> 44957 | V14: ="Q"&INT((MONTH(SalesData[[#This Row],[Order Date]])+2)/3)&"-"&YEAR(SalesData[[#This Row],[Order Date]]) -> Q1-2023
A15: ORD-202301-00013 | B15: 44929 | C15: Karan Singh | D15: Hyderabad | E15: 2427868011 | F15: JACKET | G15: PRD - 108 - JAC | H15: NorthFace | I15: Fashion | J15: North | K15: 2160.34 | L15: 89.21 | M15: North | N15: 0.041294426 | O15: Large Order | P15: Low Profit | R15: Not Returned | S15: =IF(SalesData[[#This Row],[Return Status]]="Returned",1,0) -> 0 | U15: =EOMONTH(SalesData[[#This Row],[Order Date]],0) -> 44957 | V15: ="Q"&INT((MONTH(SalesData[[#This Row],[Order Date]])+2)/3)&"-"&YEAR(SalesData[[#This Row],[Order Date]]) -> Q1-2023
A16: ORD-202301-00469 | B16: 44934 | C16: Jaya Rao | D16: Pune | E16: 487368269 | F16: Phone | G16: PRD-106-PHO | H16: Apple | I16: Electronics | J16: East | K16: 909.54 | L16: 66.36 | M16: East | N16: 0.072959958 | O16: Medium Order | P16: Low Profit | Q16: Wrong item delivered | R16: Returned | S16: =IF(SalesData[[#This Row],[Return Status]]="Returned",1,0) -> 1 | T16: 2788.38 | U16: =EOMONTH(SalesData[[#This Row],[Order Date]],0) -> 44957 | V16: ="Q"&INT((MONTH(SalesData[[#This Row],[Order Date]])+2)/3)&"-"&YEAR(SalesData[[#This Row],[Order Date]]) -> Q1-2023
A17: ORD-202301-00014 | B17: 44944 | C17: Karan Singh | D17: Pune | E17: 9232260256 | F17: watch | G17: PRD-104-WAT | H17: Fossil | I17: Accessories | J17: S | K17: 4363.39 | L17: 1142.42 | M17: South | N17: 0.26181937 | O17: Large Order | P17: High Profit | R17: Not Returned | S17: =IF(SalesData[[#This Row],[Return Status]]="Returned",1,0) -> 0 | T17: 2420.28 | U17: =EOMONTH(SalesData[[#This Row],[Order Date]],0) -> 44957 | V17: ="Q"&INT((MONTH(SalesData[[#This Row],[Order Date]])+2)/3)&"-"&YEAR(SalesData[[#This Row],[Order Date]]) -> Q1-2023
A18: ORD-202302-01176 | B18: 44960 | C18: Karan Singh | D18: Chennai | E18: 6962690222 | F18: bag | G18: PRD-105-BAG | H18: Samsonite | I18: Accessories | J18: S | K18: 538.83 | L18: 128.66 | M18: South | N18: 0.23877661 | O18: Medium Order | P18: High Profit | Q18: Late delivery | R18: Returned | S18: =IF(SalesData[[#This Row],[Return Status]]="Returned",1,0) -> 1 | U18: =EOMONTH(SalesData[[#This Row],[Order Date]],0) -> 44985 | V18: ="Q"&INT((MONTH(SalesData[[#This Row],[Order Date]])+2)/3)&"-"&YEAR(SalesData[[#This Row],[Order Date]]) -> Q1-2023
A19: ORD-202301-00015 | B19: 44943 | C19: Nikhil Roy | D19: Pune | E19: 5414586850 | F19: Laptop | G19: PRD-102-LAP | H19: Dell | I19: Electronics | J19: South | K19: 559.84 | L19: 82.48 | M19: South | N19: 0.14732781 | O19: Medium Order | P19: Medium Profit | Q19: Customer changed mind | R19: Returned | S19: =IF(SalesData[[#This Row],[Return Status]]="Returned",1,0) -> 1 | T19: 847.14 | U19: =EOMONTH(SalesData[[#This Row],[Order Date]],0) -> 44957 | V19: ="Q"&INT((MONTH(SalesData[[#This Row],[Order Date]])+2)/3)&"-"&YEAR(SalesData[[#This Row],[Order Date]]) -> Q1-2023
A20: ORD-202301-00016 | B20: 44956 | C20: Bob Johnson | D20: New Delhi | E20: 6088356159 | F20: charger | G20: PRD-111-CHA | H20: Anker | I20: Electronics | J20: South | K20: 1644.39 | L20: 358.88 | M20: South | N20: 0.21824506 | O20: Large Order | P20: High Profit | R20: Not Returned | S20: =IF(SalesData[[#This Row],[Return Status]]="Returned",1,0) -> 0 | T20: 207.68 | U20: =EOMONTH(SalesData[[#This Row],[Order Date]],0) -> 44957 | V20: ="Q"&INT((MONTH(SalesData[[#This Row],[Order Date]])+2)/3)&"-"&YEAR(SalesData[[#This Row],[Order Date]]) -> Q1-2023
A21: ORD-202301-00017 | B21: 44945 | C21: Lina Gomez | D21: New Delhi | E21: 4436995777 | F21: JACKET | G21: PRD-108-JAC | H21: NorthFace | I21: Fashion | J21: South | K21: 3301.08 | L21: 351.97 | M21: South | N21: 0.10662268 | O21: Large Order | P21: Medium Profit | R21: Not Returned | S21: =IF(SalesData[[#This Row],[Return Status]]="Returned",1,0) -> 0 | T21: 2085.91 | U21: =EOMONTH(SalesData[[#This Row],[Order Date]],0) -> 44957 | V21: ="Q"&INT((MONTH(SalesData[[#This Row],[Order Date]])+2)/3)&"-"&YEAR(SalesData[[#This Row],[Order Date]]) -> Q1-2023
A22: ORD-202301-00425 | B22: 44940 | C22: Eva Adams | D22: New Delhi | E22: 1495427707 | F22: SHOES | G22: PRD-100-SHO | H22: Nike | I22: Fashion | J22: East | K22: 2054.88 | L22: 383.2 | M22: East | N22: 0.18648291 | O22: Large Order | P22: Medium Profit | Q22: DAMAGED | R22: Returned | S22: =IF(SalesData[[#This Row],[Return Status]]="Returned",1,0) -> 1 | T22: 2793.38 | U22: =EOMONTH(SalesData[[#This Row],[Order Date]],0) -> 44957 | V22: ="Q"&INT((MONTH(SalesData[[#This Row],[Order Date]])+2)/3)&"-"&YEAR(SalesData[[#This Row],[Order Date]]) -> Q1-2023
A23: ORD-202301-00018 | B23: 44931 | C23: Karan Singh | D23: New Delhi | E23: 379176936 | F23: Headphones | G23: PRD-103-HEA | H23: Sony | I23: Electronics | J23: North | K23: 3896.53 | L23: 347.13 | M23: North | N23: 0.089086957 | O23: Large Order | P23: Low Profit | R23: Not Returned | S23: =IF(SalesData[[#This Row],[Return Status]]="Returned",1,0) -> 0 | T23: 2183.56 | U23: =EOMONTH(SalesData[[#This Row],[Order Date]],0) -> 44957 | V23: ="Q"&INT((MONTH(SalesData[[#This Row],[Order Date]])+2)/3)&"-"&YEAR(SalesData[[#This Row],[Order Date]]) -> Q1-2023
A24: ORD-202301-00019 | B24: 44954 | C24: Olivia Li | D24: Hyderabad | E24: 7986872774 | F24: jacket | G24: PRD-108-JAC | H24: NorthFace | I24: Fashion | J24: East | K24: 405.87 | L24: 43.49 | M24: East | N24: 0.10715254 | O24: Small Order | P24: Medium Profit | R24: Not Returned | S24: =IF(SalesData[[#This Row],[Return Status]]="Returned",1,0) -> 0 | T24: 2085.91 | U24: =EOMONTH(SalesData[[#This Row],[Order Date]],0) -> 44957 | V24: ="Q"&INT((MONTH(SalesData[[#This Row],[Order Date]])+2)/3)&"-"&YEAR(SalesData[[#This Row],[Order Date]]) -> Q1-2023
A25: ORD-202301-00020 | B25: 44930 | C25: Charlie Brown | D25: Chennai | E25: 1665876036 | F25: Sunglasses | G25: PRD-109-SUN | H25: RayBan | I25: Accessories | J25: West | K25: 1507.09 | L25: 203.9 | M25: West | N25: 0.13529384 | O25: Large Order | P25: Medium Profit | Q25: Customer changed mind | R25: Returned | S25: =IF(SalesData[[#This Row],[Return Status]]="Returned",1,0) -> 1 | T25: 1385.87 | U25: =EOMONTH(SalesData[[#This Row],[Order Date]],0) -> 44957 | V25: ="Q"&INT((MONTH(SalesData[[#This Row],[Order Date]])+2)/3)&"-"&YEAR(SalesData[[#This Row],[Order Date]]) -> Q1-2023
A26: ORD-202301-00021 | B26: 44953 | C26: Olivia Li | D26: Ahmedabad | E26: 656272980 | F26: shirt | G26: PRD-101-SHI | H26: Adidas | I26: Fashion | J26: South | K26: 925.01 | L26: 92.73 | M26: South | N26: 0.10024756 | O26: Medium Order | P26: Medium Profit | R26: Not Returned | S26: =IF(SalesData[[#This Row],[Return Status]]="Returned",1,0) -> 0 | T26: 2821.33 | U26: =EOMONTH(SalesData[[#This Row],[Order Date]],0) -> 44957 | V26: ="Q"&INT((MONTH(SalesData[[#This Row],[Order Date]])+2)/3)&"-"&YEAR(SalesData[[#This Row],[Order Date]]) -> Q1-2023
A27: ORD-202301-00022 | B27: 44943 | C27: Eva Adams | D27: New Delhi | E27: 8053100330 | F27: HEADPHONES | G27: PRD-103-HEA | H27: Sony | I27: Electronics | J27: East | K27: 2335.87 | L27: 231.69 | M27: East | N27: 0.099187883 | O27: Large Order | P27: Low Profit | R27: Not Returned | S27: =IF(SalesData[[#This Row],[Return Status]]="Returned",1,0) -> 0 | T27: 2183.56 | U27: =EOMONTH(SalesData[[#This Row],[Order Date]],0) -> 44957 | V27: ="Q"&INT((MONTH(SalesData[[#This Row],[Order Date]])+2)/3)&"-"&YEAR(SalesData[[#This Row],[Order Date]]) -> Q1-2023
A28: ORD-202301-00023 | B28: 44932 | C28: Eva Adams | D28: Pune | E28: 6319314919 | F28: Jacket | G28: PRD-108-JAC | H28: Unknown | I28: Fashion | J28: W | K28: 83.01 | L28: 11.9 | M28: West | N28: 0.14335622 | O28: Small Order | P28: Medium Profit | R28: Not Returned | S28: =IF(SalesData[[#This Row],[Return Status]]="Returned",1,0) -> 0 | T28: 2085.91 | U28: =EOMONTH(SalesData[[#This Row],[Order Date]],0) -> 44957 | V28: ="Q"&INT((MONTH(SalesData[[#This Row],[Order Date]])+2)/3)&"-"&YEAR(SalesData[[#This Row],[Order Date]]) -> Q1-2023
A29: ORD-202301-00024 | B29: 44949 | C29: Charlie Brown | D29: Kolkata | E29: 9877694531 | F29: headphones | G29: PRD-103-HEA | H29: Sony | I29: Electronics | J29: N | K29: 1695.26 | L29: 277.11 | M29: North | N29: 0.16346165 | O29: Large Order | P29: Medium Profit | R29: Not Returned | S29: =IF(SalesData[[#This Row],[Return Status]]="Returned",1,0) -> 0 | T29: 2183.56 | U29: =EOMONTH(SalesData[[#This Row],[Order Date]],0) -> 44957 | V29: ="Q"&INT((MONTH(SalesData[[#This Row],[Order Date]])+2)/3)&"-"&YEAR(SalesData[[#This Row],[Order Date]]) -> Q1-2023
A30: ORD-202301-00025 | B30: 44944 | C30: Frank Miller | D30: Kolkata | E30: 8083136783 | F30: Camera | G30: PRD-110-CAM | H30: Canon | I30: Electronics | J30: W | K30: 483.41 | L30: 43.43 | M30: West | N30: 0.089840922 | O30: Small Order | P30: Low Profit | R30: Not Returned | S30: =IF(SalesData[[#This Row],[Return Status]]="Returned",1,0) -> 0 | U30: =EOMONTH(SalesData[[#This Row],[Order Date]],0) -> 44957 | V30: ="Q"&INT((MONTH(SalesData[[#This Row],[Order Date]])+2)/3)&"-"&YEAR(SalesData[[#This Row],[Order Date]]) -> Q1-2023
A31: ORD-202301-00026 | B31: 44955 | C31: Hina Patel | D31: Hyderabad | E31: 5744431351 | F31: Headphones | G31: PRD-103-HEA | H31: Sony | I31: Electronics | J31: N | K31: 4902.94 | L31: 1249.32 | M31: North | N31: 0.25481038 | O31: Large Order | P31: High Profit | R31: Not Returned | S31: =IF(SalesData[[#This Row],[Return Status]]="Returned",1,0) -> 0 | T31: 2183.56 | U31: =EOMONTH(SalesData[[#This Row],[Order Date]],0) -> 44957 | V31: ="Q"&INT((MONTH(SalesData[[#This Row],[Order Date]])+2)/3)&"-"&YEAR(SalesData[[#This Row],[Order Date]]) -> Q1-2023
A32: ORD-202301-00027 | B32: 44941 | C32: Lina Gomez | D32: Kolkata | E32: 2710947775 | F32: Watch | G32: PRD-104-WAT | H32: Fossil | I32: Accessories | J32: N | K32: 2015.52 | L32: 100.78 | M32: North | N32: 0.050001985 | O32: Large Order | P32: Low Profit | R32: Not Returned | S32: =IF(SalesData[[#This Row],[Return Status]]="Returned",1,0) -> 0 | T32: 2420.28 | U32: =EOMONTH(SalesData[[#This Row],[Order Date]],0) -> 44957 | V32: ="Q"&INT((MONTH(SalesData[[#This Row],[Order Date]])+2)/3)&"-"&YEAR(SalesData[[#This Row],[Order Date]]) -> Q1-2023
A33: ORD-202301-00028 | B33: 44934 | C33: Eva Adams | D33: Pune | E33: 9993867749 | F33: Sunglasses | G33: PRD-109-SUN | H33: RayBan | I33: Accessories | J33: North | K33: 4739 | L33: 408.04 | M33: North | N33: 0.086102553 | O33: Large Order | P33: Low Profit | R33: Not Returned | S33: =IF(SalesData[[#This Row],[Return Status]]="Returned",1,0) -> 0 | U33: =EOMONTH(SalesData[[#This Row],[Order Date]],0) -> 44957 | V33: ="Q"&INT((MONTH(SalesData[[#This Row],[Order Date]])+2)/3)&"-"&YEAR(SalesData[[#This Row],[Order Date]]) -> Q1-2023
A34: ORD-202301-00029 | B34: 44934 | C34: Charlie Brown | D34: Ahmedabad | E34: 4034471349 | F34: PHONE | G34: PRD-106-PHO | H34: Unknown | I34: Electronics | J34: East | K34: 4543.89 | L34: 1150.47 | M34: East | N34: 0.25319055 | O34: Large Order | P34: High Profit | R34: Not Returned | S34: =IF(SalesData[[#This Row],[Return Status]]="Returned",1,0) -> 0 | T34: 2788.38 | U34: =EOMONTH(SalesData[[#This Row],[Order Date]],0) -> 44957 | V34: ="Q"&INT((MONTH(SalesData[[#This Row],[Order Date]])+2)/3)&"-"&YEAR(SalesData[[#This Row],[Order Date]]) -> Q1-2023
A35: ORD-202301-00030 | B35: 44954 | C35: Hina Patel | D35: Pune | E35: 4887719065 | F35: Shoes | G35: PRD - 100 - SHO | H35: Nike | I35: Fashion | J35: N | K35: 4997.87 | L35: 1057.13 | M35: North | N35: 0.21151611 | O35: Large Order | P35: High Profit | R35: Not Returned | S35: =IF(SalesData[[#This Row],[Return Status]]="Returned",1,0) -> 0 | U35: =EOMONTH(SalesData[[#This Row],[Order Date]],0) -> 44957 | V35: ="Q"&INT((MONTH(SalesData[[#This Row],[Order Date]])+2)/3)&"-"&YEAR(SalesData[[#This Row],[Order Date]]) -> Q1-2023
A36: ORD-202301-00031 | B36: 44949 | C36: Karan Singh | D36: Pune | E36: 7175655125 | F36: Watch | G36: PRD-104-WAT | H36: Unknown | I36: Accessories | J36: East | K36: 2285.03 | L36: 262.59 | M36: East | N36: 0.11491753 | O36: Large Order | P36: Medium Profit | R36: Not Returned | S36: =IF(SalesData[[#This Row],[Return Status]]="Returned",1,0) -> 0 | T36: 2420.28 | U36: =EOMONTH(SalesData[[#This Row],[Order Date]],0) -> 44957 | V36: ="Q"&INT((MONTH(SalesData[[#This Row],[Order Date]])+2)/3)&"-"&YEAR(SalesData[[#This Row],[Order Date]]) -> Q1-2023
A37: ORD-202301-00032 | B37: 44927 | C37: Nikhil Roy | D37: Hyderabad | E37: 9770348247 | F37: SHIRT | G37: PRD - 101 - SHI | H37: Adidas | I37: Fashion | J37: North | K37: 3554.72 | L37: 404.89 | M37: North | N37: 0.11390208 | O37: Large Order | P37: Medium Profit | Q37: Damaged | R37: Returned | S37: =IF(SalesData[[#This Row],[Return Status]]="Returned",1,0) -> 1 | U37: =EOMONTH(SalesData[[#This Row],[Order Date]],0) -> 44957 | V37: ="Q"&INT((MONTH(SalesData[[#This Row],[Order Date]])+2)/3)&"-"&YEAR(SalesData[[#This Row],[Order Date]]) -> Q1-2023
A38: ORD-202301-00033 | B38: 44937 | C38: Hina Patel | D38: Kolkata | E38: 8467737826 | F38: shirt | G38: PRD-101-SHI | H38: Adidas | I38: Fashion | J38: North | K38: 1712.58 | L38: 415.62 | M38: North | N38: 0.24268647 | O38: Large Order | P38: High Profit | R38: Not Returned | S38: =IF(SalesData[[#This Row],[Return Status]]="Returned",1,0) -> 0 | T38: 2821.33 | U38: =EOMONTH(SalesData[[#This Row],[Order Date]],0) -> 44957 | V38: ="Q"&INT((MONTH(SalesData[[#This Row],[Order Date]])+2)/3)&"-"&YEAR(SalesData[[#This Row],[Order Date]]) -> Q1-2023
A39: ORD-202301-00034 | B39: 44941 | C39: Jaya Rao | D39: Ahmedabad | E39: 5588675339 | F39: phone | G39: PRD - 106 - PHO | H39: Apple | I39: Electronics | J39: S | K39: 1942.67 | L39: 406.4 | M39: South | N39: 0.20919662 | O39: Large Order | P39: High Profit | Q39: Late delivery | R39: Returned | S39: =IF(SalesData[[#This Row],[Return Status]]="Returned",1,0) -> 1 | U39: =EOMONTH(SalesData[[#This Row],[Order Date]],0) -> 44957 | V39: ="Q"&INT((MONTH(SalesData[[#This Row],[Order Date]])+2)/3)&"-"&YEAR(SalesData[[#This Row],[Order Date]]) -> Q1-2023
A40: ORD-202301-00035 | B40: 44928 | C40: Ishan Kapoor | D40: Ahmedabad | E40: 1870262174 | F40: camera | G40: PRD - 110 - CAM | H40: Canon | I40: Electronics | J40: North | K40: 4771.62 | L40: 950.68 | M40: North | N40: 0.19923632 | O40: Large Order | P40: Medium Profit | R40: Not Returned | S40: =IF(SalesData[[#This Row],[Return Status]]="Returned",1,0) -> 0 | U40: =EOMONTH(SalesData[[#This Row],[Order Date]],0) -> 44957 | V40: ="Q"&INT((MONTH(SalesData[[#This Row],[Order Date]])+2)/3)&"-"&YEAR(SalesData[[#This Row],[Order Date]]) -> Q1-2023
...

Sheet Return %
A3: Row Labels | B3: Sum of Return Rate
A4: East | B4: 0.10721868
A5: North | B5: 0.098762799
A6: South | B6: 0.10174419
A7: West | B7: 0.095415778
A8: Grand Total | B8: 0.40314145

Sheet Profit & Sales by Region
A1: Region_Clean | B1: Total Sales | C1: Total Profit
A2: North | B2: 11864784 | C2: 1948886.7
A3: East | B3: 4578597.2 | C3: 759583.13
A4: South | B4: 6792448.4 | C4: 1142387.2
A5: West | B5: 4752692.4 | C5: 787018.37

Sheet Avg Profit Margin by Brand
A1: Brand | B1: Avg Profit Margin
A2: RayBan | B2: 0.16890744
A3: Adidas | B3: 0.16838405
A4: Anker | B4: 0.16829268
A5: Unknown | B5: 0.16769948
A6: Nike | B6: 0.16762456
A7: Fossil | B7: 0.16753039
A8: Samsonite | B8: 0.16686785
A9: Apple | B9: 0.16522243
A10: Canon | B10: 0.16410618
A11: Samsung | B11: 0.16401588
A12: Sony | B12: 0.16355969
A13: Dell | B13: 0.16233255
A14: NorthFace | B14: 0.16176615
